Workbook

Sheet Assumptions
A1: BERLITZ COST MODEL — GLOBAL ASSUMPTIONS (v0.2)
A2: BLUE = input · BLACK = formula · GREEN = cross-sheet link · YELLOW = placeholder needing real data
A4: SESSION SETUP (30-min sessions; tiers differ by feature mix, not length)
A5: Standard session length (min) | B5: 30
A6: STT share of session (%) | B6: 0.15
A7: TTS share of session (%) | B7: 0.05
A8: AI tutor share of session — Plus/Pro (%) | B8: 0.3
A9: LLM dialogue tokens / session (k) — Plus/Pro | B9: 10
A10: Pronunciation coverage of user-speech / STT (%) | B10: 1
A11: PRICING & PLANS (subscription, monthly $)
A12: Free plan price ($/mo) | B12: 0
A13: Plus plan price ($/mo) | B13: 19
A14: Pro plan price ($/mo) | B14: 49
A15: Enterprise plan price ($/mo) | B15: 80
A16: Payment processing % of revenue | B16: 0.025
A18: BEST TIER HUMAN ECONOMICS
A19: Teacher pay per session (€) — live + prep | B19: 10
A20: Live delivery infra per session (€) — fully loaded | B20: 5.8
A21: No-show rate | B21: 0.1
A22: Teacher paid % on no-show | B22: 0.5
A24: ANNUAL FIXED COSTS (€/yr — all placeholders, refine with real data)
A25: Curriculum content generation (€/yr) — Content Generation sheet | B25: ='Content Generation'!B34 -> 557329.92
A26: Platform infra (€/yr) | B26: 600000
A27: R&D, QA, compliance (€/yr) | B27: 400000
A28: Customer support (€/yr) | B28: 250000
A29: TOTAL fixed (€/yr) | B29: =SUM(B25:B28) -> 1807329.9
A30: Fixed cost per session (€) — flat allocation | B30: =Assumptions!$B$29/Assumptions!$B$41 -> 0.016960679
A32: MOBILE APP PLANS — credits & references
A33: Plus credits / month | B33: 2
A34: Pro credits / month | B34: 6
A35: Plus price (Rs/mo, ref) | B35: 999
A36: Pro price (Rs/mo, ref) | B36: 1999
A37: Markets | B37: India, Chile
A39: GLOBAL
A40: USD → EUR FX rate | B40: 0.92
A41: Total annual AI sessions (for content allocation) | B41: ='User & Revenue Model'!F27 -> 106560000

Sheet Feature Cost Build
A1: FEATURE COST BUILD — per-tier AI-session cost. Uniform 30-min session; tiers differ by feature time-mix. Human teacher costed separately.
A2: Each row = a feature. Intensity = minutes/tokens/... per session. Per-tier unit cost reflects each tier’s selected vendor. Cost = unit × intensity.
A4: Feature | B4: Unit driver | C4: Unit € (Plus ref) | D4: Free intensity | E4: Plus intensity | F4: Pro intensity | G4: Cost / Free (€) | H4: Cost / Plus (€) | I4: Cost / Pro (€) | K4: Free unit € | L4: Plus unit € | M4: Pro unit €
A5: Basic curriculum (2026 baseline) | B5: Allocated via fixed costs | C5: =L5 -> 0 | D5: =1 -> 1 | E5: =1 -> 1 | F5: =1 -> 1 | G5: =K5*D5 -> 0 | H5: =L5*E5 -> 0 | I5: =M5*F5 -> 0 | K5: 0 | L5: 0 | M5: 0
A6: LLM inference / dialogue | B6: tokens (1k blended) | C6: =L6 -> 0.00552 | D6: 5 | E6: =Assumptions!$B$9 -> 10 | F6: =Assumptions!$B$9 -> 10 | G6: =K6*D6 -> 0.0092 | H6: =L6*E6 -> 0.0552 | I6: =M6*F6 -> 0.0552 | K6: ='Tool — LLM'!$C$14*Assumptions!$B$40 -> 0.00184 | L6: ='Tool — LLM'!$C$15*Assumptions!$B$40 -> 0.00552 | M6: ='Tool — LLM'!$C$16*Assumptions!$B$40 -> 0.00552
A7: Voice — ASR (speech-to-text) | B7: voice-minutes | C7: =L7 -> 0.003864 | D7: =Assumptions!$B$6*Assumptions!$B$5 -> 4.5 | E7: =Assumptions!$B$6*Assumptions!$B$5 -> 4.5 | F7: =Assumptions!$B$6*Assumptions!$B$5 -> 4.5 | G7: =K7*D7*IF('Tool — Avatar'!$B$18="Talkio.ai",0,1) -> 0.017388 | H7: =L7*E7*IF('Tool — Avatar'!$B$19="Talkio.ai",0,1) -> 0.017388 | I7: =M7*F7*IF('Tool — Avatar'!$B$20="Talkio.ai",0,1) -> 0.017388 | K7: ='Tool — Voice AI'!$C$14*Assumptions!$B$40 -> 0.003864 | L7: ='Tool — Voice AI'!$C$15*Assumptions!$B$40 -> 0.003864 | M7: ='Tool — Voice AI'!$C$16*Assumptions!$B$40 -> 0.003864
A8: AI tutor (interactive avatar) | B8: avatar-minutes | C8: =L8 -> 0.0092 | D8: 0 | E8: =Assumptions!$B$8*Assumptions!$B$5 -> 9 | F8: =Assumptions!$B$8*Assumptions!$B$5 -> 9 | G8: =K8*D8 -> 0 | H8: =L8*E8 -> 0.0828 | I8: =M8*F8 -> 0.0828 | K8: ='Tool — Avatar'!$C$18*Assumptions!$B$40 -> 0.0092 | L8: ='Tool — Avatar'!$C$19*Assumptions!$B$40 -> 0.0092 | M8: ='Tool — Avatar'!$C$20*Assumptions!$B$40 -> 0.0092
A9: Human teacher (live + prep) — costed per booking | B9: 1 session | C9: =(Assumptions!$B$19+Assumptions!$B$20)*(1+Assumptions!$B$21/(1-Assumptions!$B$21)*Assumptions!$B$22) -> 16.677778 | D9: 0 | E9: 0 | F9: 0 | G9: =K9*D9 -> 0 | H9: =L9*E9 -> 0 | I9: =M9*F9 -> 0 | K9: =$C$9 -> 16.677778 | L9: =$C$9 -> 16.677778 | M9: =$C$9 -> 16.677778
A10: Pronunciation assessment (user speech) | B10: minutes (user speech) | C10: =L10 -> 0.0046 | D10: =Assumptions!$B$10*D7 -> 4.5 | E10: =Assumptions!$B$10*E7 -> 4.5 | F10: =Assumptions!$B$10*F7 -> 4.5 | G10: =K10*D10 -> 0.0207 | H10: =L10*E10 -> 0.0207 | I10: =M10*F10 -> 0.0207 | K10: ='Tool — Pronunciation'!$C$13*Assumptions!$B$40 -> 0.0046 | L10: ='Tool — Pronunciation'!$C$14*Assumptions!$B$40 -> 0.0046 | M10: ='Tool — Pronunciation'!$C$15*Assumptions!$B$40 -> 0.0046
A11: Voice — TTS (text-to-speech) | B11: voice-minutes | C11: =L11 -> 0.0138 | D11: =Assumptions!$B$7*Assumptions!$B$5 -> 1.5 | E11: =Assumptions!$B$6*Assumptions!$B$5 -> 4.5 | F11: =Assumptions!$B$6*Assumptions!$B$5 -> 4.5 | G11: =K11*D11*IF('Tool — Avatar'!$B$18="Talkio.ai",0,1) -> 0.009315 | H11: =L11*E11*IF('Tool — Avatar'!$B$19="Talkio.ai",0,1) -> 0.0621 | I11: =M11*F11*IF('Tool — Avatar'!$B$20="Talkio.ai",0,1) -> 0.207 | K11: ='Tool — Voice AI'!$C$28*Assumptions!$B$40 -> 0.00621 | L11: ='Tool — Voice AI'!$C$29*Assumptions!$B$40 -> 0.0138 | M11: ='Tool — Voice AI'!$C$30*Assumptions!$B$40 -> 0.046
A12: Payment processing — excluded (see P&L) | B12: — | C12: =L12 -> 0 | D12: 0 | E12: 0 | F12: 0 | G12: =K12*D12 -> 0 | H12: =L12*E12 -> 0 | I12: =M12*F12 -> 0 | K12: 0 | L12: 0 | M12: 0
A13: VARIABLE COST PER SESSION | G13: =SUM(G5:G12) -> 0.056603 | H13: =SUM(H5:H12) -> 0.238188 | I13: =SUM(I5:I12) -> 0.383088
A14: Content/curriculum generation (amortised €/session) | G14: ='Content Generation'!$B$34/Assumptions!$B$41 -> 0.0052301982 | H14: ='Content Generation'!$B$34/Assumptions!$B$41 -> 0.0052301982 | I14: ='Content Generation'!$B$34/Assumptions!$B$41 -> 0.0052301982
A15: TOTAL COST / SESSION incl. content (€) | G15: =G13+G14 -> 0.061833198 | H15: =H13+H14 -> 0.2434182 | I15: =I13+I14 -> 0.3883182
A17: Other fixed costs (platform, R&D, support, engine) — annual lump in User & Revenue P&L.
A20: SRIKANT'S SIMPLIFIED MODEL — per 1,000 users / month (5 tiers)
A21: Reverse-engineered from Srikant’s table: flat $2 AI/user/mo · teacher light · ~16% app-store fee · LTV ≈ 16.5 × monthly price. Sessions/mo = added assumption (not in his model).
A22: App-store / payment fee % of revenue | B22: 0.16
A23: Tier | B23: Users /1k | C23: Price $/mo | D23: AI $/user/mo | E23: Teacher $/user/mo | F23: Sessions/user/mo | G23: Price / session $ | H23: Cost / session $ | I23: Revenue $/mo | J23: AI+Teacher $/mo | K23: App-fee $/mo | L23: Gross profit $/mo | M23: LTV $
A24: Free | B24: 800 | C24: 0 | D24: 2 | E24: 0 | F24: 8 | G24: =IFERROR(C24/F24,0) -> 0 | H24: =IFERROR((D24+E24)/F24,0) -> 0.25 | I24: =B24*C24 -> 0 | J24: =B24*(D24+E24) -> 1600 | K24: =I24*$B$22 -> 0 | L24: =I24-J24-K24 -> -1600 | M24: =C24*16.5 -> 0
A25: Plus | B25: 60 | C25: 19 | D25: 2 | E25: 0 | F25: 10 | G25: =IFERROR(C25/F25,0) -> 1.9 | H25: =IFERROR((D25+E25)/F25,0) -> 0.2 | I25: =B25*C25 -> 1140 | J25: =B25*(D25+E25) -> 120 | K25: =I25*$B$22 -> 182.4 | L25: =I25-J25-K25 -> 837.6 | M25: =C25*16.5 -> 313.5
A26: Pro | B26: 60 | C26: 49 | D26: 2 | E26: 3.75 | F26: 12 | G26: =IFERROR(C26/F26,0) -> 4.0833333 | H26: =IFERROR((D26+E26)/F26,0) -> 0.47916667 | I26: =B26*C26 -> 2940 | J26: =B26*(D26+E26) -> 345 | K26: =I26*$B$22 -> 470.4 | L26: =I26-J26-K26 -> 2124.6 | M26: =C26*16.5 -> 808.5
A27: Career | B27: 40 | C27: 40 | D27: 2 | E27: 5 | F27: 10 | G27: =IFERROR(C27/F27,0) -> 4 | H27: =IFERROR((D27+E27)/F27,0) -> 0.7 | I27: =B27*C27 -> 1600 | J27: =B27*(D27+E27) -> 280 | K27: =I27*$B$22 -> 256 | L27: =I27-J27-K27 -> 1064 | M27: =C27*16.5 -> 660
A28: Premium | B28: 40 | C28: 100 | D28: 2 | E28: 15 | F28: 15 | G28: =IFERROR(C28/F28,0) -> 6.6666667 | H28: =IFERROR((D28+E28)/F28,0) -> 1.1333333 | I28: =B28*C28 -> 4000 | J28: =B28*(D28+E28) -> 680 | K28: =I28*$B$22 -> 640 | L28: =I28-J28-K28 -> 2680 | M28: =C28*16.5 -> 1650
A29: TOTAL | B29: =SUM(B24:B28) -> 1000 | I29: =SUM(I24:I28) -> 9680 | J29: =SUM(J24:J28) -> 3025 | K29: =SUM(K24:K28) -> 1548.8 | L29: =SUM(L24:L28) -> 5106.2

Sheet User & Revenue Model
A1: USER & REVENUE MODEL — Free / Plus / Pro subscriptions + credits
A2: BLUE = input · BLACK = formula · GREEN = link · YELLOW = key assumption. Plans: Plus $19/mo (2 credits), Pro $49/mo (6 credits). Revenue $→€ via Assumptions!B5.
A4: USER BASE & CONVERSION FUNNEL
A5: Freemium signups | B5: 1000000 | C5: Free-tier registered users
A6: Free → paid conversion rate | B6: 0.2 | C6: Stated range 18–25%
A7: Total paid subscribers | B7: =B5*B6 -> 200000
A8: % of paid on Pro | B8: 0.3 | C8: Remainder on Plus
A9: Plus subscribers | B9: =B7*(1-B8) -> 140000
A10: Pro subscribers | B10: =B7*B8 -> 60000
A11: Free (non-converting) users | B11: =B5-B7 -> 800000 | C11: Cost-bearing, no revenue
A12: Enterprise users | B12: 500000 | C12: B2B seats — Pro-style usage, annual ARPU
A13: Total cost-bearing users | B13: =B11+B9+B10+B12 -> 1500000
A15: UNIT COSTS / SESSION (linked from Feature Cost Build)
A16: Free AI session incl. content (€) | B16: ='Feature Cost Build'!G15 -> 0.061833198
A17: Plus AI session incl. content (€) | B17: ='Feature Cost Build'!H15 -> 0.2434182
A18: Pro AI session incl. content (€) | B18: ='Feature Cost Build'!I15 -> 0.3883182
A19: Human teacher session (€) | B19: ='Feature Cost Build'!C9 -> 16.677778 | C19: Live + prep incl. no-show
A21: SEGMENT ECONOMICS (annual)
B22: Free | C22: Plus | D22: Pro | E22: Enterprise | F22: Total
A23: Subscribers / users | B23: =B11 -> 800000 | C23: =B9 -> 140000 | D23: =B10 -> 60000 | E23: =B12 -> 500000 | F23: =SUM(B23:E23) -> 1500000
A24: Plan price ($/seat/mo) | B24: 0 | C24: =Assumptions!B13 -> 19 | D24: =Assumptions!B14 -> 49 | E24: 150
A25: AI sessions / user / mo | B25: 5 | C25: 10 | D25: 8 | E25: 6 | G25: Free uncapped; Plus/Pro ≤ credits
A26: Human sessions / user / mo | B26: 0 | C26: 0 | D26: 2 | E26: 2 | G26: Pro/Enterprise live bookings | H26: minutes of session | I26: avatar minutes
A27: Annual AI sessions | B27: =B23*B25*12 -> 48000000 | C27: =C23*C25*12 -> 16800000 | D27: =D23*D25*12 -> 5760000 | E27: =E23*E25*12 -> 36000000 | F27: =SUM(B27:E27) -> 106560000 | H27: =SUM(C27:E27)*30 -> 1756800000 | I27: =H27/Assumptions!B8 -> 5856000000
A28: Annual human sessions | B28: =B23*B26*12 -> 0 | C28: =C23*C26*12 -> 0 | D28: =D23*D26*12 -> 1440000 | E28: =E23*E26*12 -> 12000000 | F28: =SUM(B28:E28) -> 13440000
A29: AI cost / session (€) | B29: =$B$16 -> 0.061833198 | C29: =$B$17 -> 0.2434182 | D29: =$B$18 -> 0.3883182 | E29: =$B$18 -> 0.3883182
A30: Annual AI cost (€) | B30: =B27*B29 -> 2967993.5 | C30: =C27*C29 -> 4089425.7 | D30: =D27*D29 -> 2236712.8 | E30: =E27*E29 -> 13979455 | F30: =SUM(B30:E30) -> 23273587 | G30: =F30/B40 -> 0.02615527 | H30: ai cost overall relative to total revenue
A31: Annual human cost (€) | B31: =B28*$B$19 -> 0 | C31: =C28*$B$19 -> 0 | D31: =D28*$B$19 -> 24016000 | E31: =E28*$B$19 -> 2.0013333e+08 | F31: =SUM(B31:E31) -> 2.2414933e+08
A32: Annual variable cost (€) | B32: =B30+B31 -> 2967993.5 | C32: =C30+C31 -> 4089425.7 | D32: =D30+D31 -> 26252713 | E32: =E30+E31 -> 2.1411279e+08 | F32: =SUM(B32:E32) -> 2.4742292e+08
A33: Annual revenue ($) | B33: 0 | C33: =C23*C24*12 -> 31920000 | D33: =D23*D24*12 -> 35280000 | E33: =E23*E24*12 -> 900000000 | F33: =SUM(B33:E33) -> 967200000
A34: Annual revenue (€) | B34: =B33*Assumptions!$B$40 -> 0 | C34: =C33*Assumptions!$B$40 -> 29366400 | D34: =D33*Assumptions!$B$40 -> 32457600 | E34: =E33*Assumptions!$B$40 -> 828000000 | F34: =SUM(B34:E34) -> 889824000
A35: Margin (€) | B35: =B34-B32 -> -2967993.5 | C35: =C34-C32 -> 25276974 | D35: =D34-D32 -> 6204887.2 | E35: =E34-E32 -> 6.1388721e+08
A36: Operating Margin (%) | B36: negative | C36: =1-C32/C34 -> 0.86074474 | D36: =1-D32/D34 -> 0.19116901 | E36: =1-E32/E34 -> 0.74140968
C37: =C30/C34 -> 0.13925526 | D37: =D30/D34 -> 0.068911836 | E37: =E30/E34 -> 0.0168834
A39: P&L SUMMARY (€/yr)
A40: Gross revenue (€) | B40: =F34 -> 889824000 | D40: ARPU | E40: =(B40/F23)/12 -> 49.434667
A41: Payment processing (€) | B41: =B40*Assumptions!B16 -> 22245600 | C41: 2.5% of revenue
A42: Net revenue (€) | B42: =B40-B41 -> 867578400
A43: Variable cost — AI + human (€) | B43: =F32 -> 2.4742292e+08
A44: Contribution margin (€) | B44: =B42-B43 -> 6.2015548e+08
...

Sheet Content Generation
A1: CONTENT / CURRICULUM GENERATION — AI-ASSISTED HYBRID BUILD
A2: BLUE = input · BLACK = formula · GREEN = cross-sheet link · YELLOW = key assumption. Feeds Assumptions!B28 (curriculum line).
A4: CONTENT CATALOG SCOPE
A5: Languages in catalog | B5: 12 | C5: Distinct languages offered
A6: CEFR levels per language (A1–C2) | B6: 6 | C6: A1, A2, B1, B2, C1, C2
A7: Lessons per level | B7: 50 | C7: Authored lesson units per level
A8: Total lessons in catalog | B8: =B5*B6*B7 -> 3600 | C8: languages x levels x lessons
A10: PER-LESSON GENERATION COST — AI-ASSISTED HYBRID
A11: AI draft (LLM generation)
A12: Tokens per lesson (blended in+out) | B12: 50000 | C12: Prompt + generated lesson content
A13: LLM cost per 1k tokens (€) | B13: ='Tool — LLM'!$C$15*Assumptions!$B$40 -> 0.00552 | C13: Selected LLM USD price × FX (Assumptions!B5)
A14: AI generation cost / lesson (€) | B14: =B12/1000*B13 -> 0.276
A15: Human review & edit
A16: Editor / SME hours per lesson | B16: 4 | C16: Instructional-design review of AI draft
A17: Loaded editor rate (€/hr) | B17: 60 | C17: Fully-loaded hourly cost
A18: Human review cost / lesson (€) | B18: =B16*B17 -> 240 | C18: hours x rate
A19: Media & localization
A20: Media / audio / localization per lesson (€) | B20: 50 | C20: Recording, images, QA per lesson
A21: TOTAL COST PER LESSON (€) | B21: =B14+B18+B20 -> 290.276 | C21: AI + human + media
A23: ONE-TIME BUILD (amortised)
A24: Total initial build cost (€) | B24: =B8*B21 -> 1044993.6 | C24: total lessons x cost/lesson
A25: Amortisation period (years) | B25: 3 | C25: Useful life of authored catalog
A26: Amortised build cost (€/yr) | B26: =B24/B25 -> 348331.2 | C26: build / years
A28: ANNUAL REFRESH
A29: Annual refresh rate (% of catalog/yr) | B29: 0.2 | C29: Share of lessons re-authored each year
A30: Lessons refreshed per year | B30: =B8*B29 -> 720 | C30: total lessons x refresh %
A31: Annual refresh cost (€/yr) | B31: =B30*B21 -> 208998.72 | C31: refreshed lessons x cost/lesson
A33: TOTAL ANNUAL CONTENT GENERATION COST
A34: TOTAL CONTENT GENERATION (€/yr) | B34: =B26+B31 -> 557329.92 | C34: Amortised build + annual refresh → feeds Assumptions!B28

Sheet Tool — Avatar
A1: AVATAR VENDOR DECISION
A2: Per-minute video avatar. NOTE: Talkio.ai bundles ASR+TTS+LLM — selecting it zeroes that tier’s separate voice cost.
A4: VENDOR COMPARISON
A5: Vendor | B5: Price (USD) | C5: Unit | D5: Notes
A6: Simli Trinity-1 | B6: 0.01 | C6: $/min | D6: Lip-sync only — you add voice
A7: Simli standard | B7: 0.05 | C7: $/min | D7: "Legacy" model | E7: https://www.simli.com/pricing
A8: HeyGen LiveAvatar Lite | B8: 0.1 | C8: $/min | D8: HeyGen consumer plans are credit-based video gen; interactive-avatar (streaming) API = enterprise/quote. Not public per-min. Estimate | E8: https://www.heygen.com/pricing
A9: Anam.ai | B9: 0.2 | C9: $/min | D9: Conversational; check voice bundling
A10: HeyGen LiveAvatar Full | B10: 0.19 | C10: $/min | D10: Higher fidelity
A11: Tavus CVI | B11: 0.37 | C11: $/min | D11: Conversational video; bundles voice. NOT validated live | E11: https://www.tavus.io/pricing
A12: D-ID Streaming | B12: 0.3 | C12: $/min | D12: Premium/enterprise | E12: https://www.d-id.com/pricing/api/
A13: Talkio.ai | B13: 0.3 | C13: $/min | D13: Talkio bundles ASR+TTS+LLM. Price is placeholder — confirm vs contract (char + per-seat)
A14: On-device (in-house) | B14: 0.005 | C14: $/min | D14: Local rendering
A16: SELECTED VENDOR — per tier (Free / Plus / Pro)
A17: Tier | B17: Vendor (change me) | C17: Price (USD)
A18: Free | B18: Simli Trinity-1 | C18: =VLOOKUP(B18,$A$6:$B$14,2,FALSE()) -> 0.01
A19: Plus | B19: Simli Trinity-1 | C19: =VLOOKUP(B19,$A$6:$B$14,2,FALSE()) -> 0.01
A20: Pro | B20: Simli Trinity-1 | C20: =VLOOKUP(B20,$A$6:$B$14,2,FALSE()) -> 0.01

Sheet Tool — Voice AI
A1: VOICE — ASR (speech-to-text) + TTS (text-to-speech) — priced SEPARATELY
A2: ASR and TTS have very different pricing, so split. Per-minute, per tier. Azure = current Berlitz voice stack.
A4: ASR / SPEECH-TO-TEXT — VENDOR COMPARISON
A5: Vendor | B5: Price (USD) | C5: Unit | D5: Notes
A6: Azure Speech (committed) | B6: 0.0083 | C6: $/min | D6: Azure STT committed: $0.50/hr @50k-hr tier = $0.0083/min; 10k-hr tier $0.65/hr=$0.0108; PAYG $1/hr. Validated Jun2026 | E6: https://azure.microsoft.com/en-us/pricing/details/speech/
A7: Deepgram Nova | B7: 0.0042 | C7: $/min | D7: Nova-3 Monolingual, Growth (prepaid annual ~20% off); PAYG $0.0048 promo. Validated Jun 2026 | E7: https://deepgram.com/pricing
A8: Whisper (self-hosted) | B8: 0.006 | C8: $/min | D8: OSS self-host; infra cost. ~$0.006/min ref | E8: https://deepgram.com/pricing
A9: OpenAI gpt-4o-mini-transcribe | B9: 0.003 | C9: $/min | D9: gpt-4o-mini-transcribe $0.003/min (gpt-4o-transcribe $0.006). Validated Jun2026
A10: On-device (in-house) | B10: 0.002 | C10: $/min | D10: Local model
A12: SELECTED ASR — per tier (Free / Plus / Pro)
A13: Tier | B13: Vendor (change me) | C13: Price (USD)
A14: Free | B14: Deepgram Nova | C14: =VLOOKUP(B14,$A$6:$B$10,2,FALSE()) -> 0.0042
A15: Plus | B15: Deepgram Nova | C15: =VLOOKUP(B15,$A$6:$B$10,2,FALSE()) -> 0.0042
A16: Pro | B16: Deepgram Nova | C16: =VLOOKUP(B16,$A$6:$B$10,2,FALSE()) -> 0.0042
A18: TTS / TEXT-TO-SPEECH — VENDOR COMPARISON
A19: Vendor | B19: Price (USD) | C19: Unit | D19: Notes
A20: Azure Neural TTS (committed) | B20: 0.00675 | C20: $/min | D20: Azure Neural TTS committed $7.50/1M chars (2,000M tier) x ~900 ch/min = $0.0068/min (=EUR6.451/1M). Validated Jun2026 | E20: https://azure.microsoft.com/en-us/pricing/details/speech/
A21: OpenAI TTS | B21: 0.015 | C21: $/min | D21: OpenAI now token/realtime-centric; classic tts ~$15/1M chars (~$0.0135/min); confirm. Page validated Jun2026 | E21: https://platform.openai.com/docs/pricing
A22: ElevenLabs Turbo | B22: 0.05 | C22: $/min | D22: ElevenLabs Business plan, low-latency TTS ~$0.05/min; Enterprise lower at scale. Validated Jun 2026 | E22: https://elevenlabs.io/pricing
A23: ElevenLabs Premium | B23: 0.17 | C23: $/min | D23: ElevenLabs standard quality ~$0.17/min (Creator..Business). Validated Jun 2026 | E23: https://elevenlabs.io/pricing
A24: On-device (in-house) | B24: 0.01 | C24: $/min | D24: Local model
A26: SELECTED TTS — per tier (Free / Plus / Pro)
A27: Tier | B27: Vendor (change me) | C27: Price (USD)
A28: Free | B28: Azure Neural TTS (committed) | C28: =VLOOKUP(B28,$A$20:$B$24,2,FALSE()) -> 0.00675
A29: Plus | B29: OpenAI TTS | C29: =VLOOKUP(B29,$A$20:$B$24,2,FALSE()) -> 0.015
A30: Pro | B30: ElevenLabs Turbo | C30: =VLOOKUP(B30,$A$20:$B$24,2,FALSE()) -> 0.05

Sheet Tool — Pronunciation
A1: PRONUNCIATION ASSESSMENT — time-based ($/min), runs on user speech
A2: Runs whenever the user speaks = user-speech (STT) minutes x coverage (Assumptions!B10). Azure = current Berlitz stack. Validated Jun 2026.
A4: VENDOR COMPARISON
A5: Vendor | B5: Price (USD) | C5: Unit | D5: Notes
A6: Azure Pronunciation Assessment | B6: 0.005 | C6: $/min | D6: $0.30/hr PAYG; CURRENT Berlitz stack (Teams) | E6: https://azure.microsoft.com/en-us/pricing/details/speech/
A7: Azure committed (50k-hr) | B7: 0.0025 | C7: $/min | D7: $0.15/hr committed tier (2M-user scale) | E7: https://azure.microsoft.com/en-us/pricing/details/speech/
A8: Speechace (per-utterance, est) | B8: 0.02 | C8: $/min | D8: Natively per-utterance; rough per-min equiv | E8: https://www.speechace.com/ | F8: https://shop.speechace.com/subscription/signup-api/speechace-for-developers/speechace_api_premium_500_monthly
A9: On-device (in-house) | B9: 0.001 | C9: $/min | D9: Local model
A11: SELECTED VENDOR — per tier (Free / Plus / Pro)
A12: Tier | B12: Vendor (change me) | C12: Price (USD)
A13: Free | B13: Azure Pronunciation Assessment | C13: =VLOOKUP(B13,$A$6:$B$9,2,FALSE()) -> 0.005
A14: Plus | B14: Azure Pronunciation Assessment | C14: =VLOOKUP(B14,$A$6:$B$9,2,FALSE()) -> 0.005
A15: Pro | B15: Azure Pronunciation Assessment | C15: =VLOOKUP(B15,$A$6:$B$9,2,FALSE()) -> 0.005

Sheet Tool — LLM
A1: LLM (TEXT) VENDOR DECISION
A2: Blended input+output token cost. Per 1,000 tokens.
A4: VENDOR COMPARISON
A5: Vendor | B5: Price (USD) | C5: Unit | D5: Notes
A6: Claude Haiku 4.5 | B6: 0.002 | C6: $/1k tokens (blended) | D6: Haiku 4.5: $1 in / $5 out per MTok; blended ~3:1 mix = ~$2/MTok. Batch -50%. Validated Jun 2026 | E6: https://claude.com/pricing
A7: Claude Sonnet 4.6 (default) | B7: 0.006 | C7: $/1k tokens (blended) | D7: Sonnet 4.6: $3 in / $15 out per MTok; blended ~3:1 = ~$6/MTok. Validated Jun 2026 | E7: https://claude.com/pricing
A8: Claude Opus 4.6 | B8: 0.01 | C8: $/1k tokens (blended) | D8: Opus 4.8: $5 in / $25 out per MTok; blended ~3:1 = ~$10/MTok. Validated Jun 2026 | E8: https://claude.com/pricing
A9: GPT-class equivalent | B9: 0.003 | C9: $/1k tokens (blended) | D9: Pricing comparable
A10: OSS self-hosted | B10: 0.0003 | C10: $/1k tokens (blended) | D10: Requires infra investment
A11: On-device (in-house) | B11: 0.0001 | C11: $/1k tokens (blended) | D11: In-house on-device small model
A12: SELECTED VENDOR — per tier (Free / Plus / Pro)
A13: Tier | B13: Vendor (change me) | C13: Price (USD)
A14: Free | B14: Claude Haiku 4.5 | C14: =VLOOKUP(B14,$A$6:$B$11,2,FALSE()) -> 0.002
A15: Plus | B15: Claude Sonnet 4.6 (default) | C15: =VLOOKUP(B15,$A$6:$B$11,2,FALSE()) -> 0.006
A16: Pro | B16: Claude Sonnet 4.6 (default) | C16: =VLOOKUP(B16,$A$6:$B$11,2,FALSE()) -> 0.006

Sheet Open Items
A1: OPEN ITEMS — refine before any decision (tiers per berlitz-mobile-app.md)
A3: CATEGORY | B3: STATUS | C3: ITEM
A4: Volume | B4: Placeholder 1M/yr | C4: Annual sessions for fixed allocation — confirm year-3 target
A5: Baseline | B5: Confirmed (550k/800) | C5: Global EU/JP/US, no franchises
A6: Engagement | B6: Now modelled (User & Revenue) | C6: Sessions/user/mo per segment + DAU; refine 4–8 range & enterprise frequency
A7: Tier mix | B7: Modelled as scenarios | C7: Pick target mix once strategy lands
A8: Tool — Voice AI | B8: OpenAI Realtime default | C8: Validate per actual vendor
A9: Tool — Avatar | B9: HeyGen Lite default | C9: Trial Simli, Anam vs. Talkio.ai baseline for fidelity
A10: Tool — Pronunciation | B10: Speechace default | C10: Vendor & pricing — could self-host
A11: Tool — LLM | B11: Claude Sonnet default | C11: Token budget per session is biggest uncertainty
A12: No-show | B12: Placeholder 10% / 50%-pay | C12: Actual rate from Berlitz ops
A13: Curriculum content | B13: Now modelled (Content Gen sheet) | C13: Validate per-lesson inputs: tokens/lesson, editor hours, refresh %, catalog scope
A14: Closed-loop engine | B14: Placeholder €300k/yr | C14: Build cost for adaptive engine
... A29: Markets | B29: India + Chile pilot | C29: Rs pricing (999/1999); 1k-signup conversion matrix in doc for pilot sizing
