Workbook

Sheet Assumptions
A1: BERLITZ COST MODEL — GLOBAL ASSUMPTIONS (v0.2.8)
A2: BLUE = input · BLACK = formula · GREEN = cross-sheet link · YELLOW = placeholder needing real data
A4: SESSION SETUP (30-min sessions; tiers differ by feature mix, not length)
A5: Standard session length (min) | B5: 30
A6: STT share of session (%) | B6: 0.15
A7: TTS share of session (%) | B7: 0.05
A8: AI tutor share of session — Plus/Pro/Career/Ent (%) | B8: 0.3
A9: LLM dialogue tokens / session (k) — Plus/Pro/Career/Ent | B9: 10
A10: Pronunciation coverage of user-speech / STT (%) | B10: 1
A11: PRICING & PLANS (subscription, monthly $)
A12: Free plan price ($/mo) | B12: 0
A13: Plus plan price ($/mo) | B13: 19
A14: Pro plan price ($/mo) | B14: 49
A15: Premium plan price ($/mo) | B15: 100
A16: Payment processing % of revenue | B16: 0.025
A17: Career plan price ($/mo) | B17: 39
A18: BEST TIER HUMAN ECONOMICS
A19: Teacher pay per session (€) — live + prep | B19: 10
A20: Live delivery infra per session (€) — fully loaded | B20: 5.8
A21: No-show rate | B21: 0.1
A22: Teacher paid % on no-show | B22: 0.5
A24: ANNUAL FIXED COSTS (€/yr — all placeholders, refine with real data)
A25: Curriculum content generation (€/yr) — Content Generation sheet | B25: ='Content Generation'!B34 -> 557329.92
A26: Platform infra (€/yr) | B26: 600000
A27: R&D, QA, compliance (€/yr) | B27: 400000
A28: Customer support (€/yr) | B28: 250000
A29: TOTAL fixed (€/yr) | B29: =SUM(B25:B28) -> 1807329.9
A30: Fixed cost per session (€) — flat allocation | B30: =Assumptions!$B$29/Assumptions!$B$41 -> 0.070709308
A32: MOBILE APP PLANS — credits & references
A33: Plus credits / month | B33: 2
A34: Pro credits / month | B34: 6
A35: Plus price (Rs/mo, ref) | B35: 999
A36: Pro price (Rs/mo, ref) | B36: 1999
A37: Markets | B37: India, Chile
A39: GLOBAL
A40: USD → EUR FX rate | B40: 0.92
A41: Total annual AI sessions (for content allocation) | B41: ='User & Revenue Model'!H27+'User & Revenue Model'!H28 -> 25560000

Sheet Feature Cost Build
A1: FEATURE COST BUILD — per-tier AI-session cost. Uniform 30-min session; tiers differ by feature time-mix. Human teacher costed separately.
A2: Each row = a feature. Intensity = minutes/tokens/utterances per session. Per-tier unit cost reflects each tier’s selected vendor. Cost = unit × intensity.
A4: AI Powered Practice
A5: Feature | B5: Unit driver | C5: Unit € (Plus ref) | D5: Free intensity | E5: Plus intensity | F5: Pro intensity | G5: Career intensity | H5: Premium intensity | I5: Enterprise intensity | K5: Cost / Free (€) | L5: Cost / Plus (€) | M5: Cost / Pro (€) | N5: Cost / Career (€) | O5: Cost / Premium (€) | P5: Cost / Enterprise (€) | R5: Free unit € | S5: Plus unit € | T5: Pro unit € | U5: Career unit € | V5: Premium unit € | W5: Enterprise unit €
A6: Basic curriculum (2026 baseline) | B6: Allocated via fixed costs | C6: =S6 -> 0 | D6: =1 -> 1 | E6: =1 -> 1 | F6: =1 -> 1 | G6: =1 -> 1 | H6: =1 -> 1 | I6: =1 -> 1 | K6: =R6*D6 -> 0 | L6: =S6*E6 -> 0 | M6: =T6*F6 -> 0 | N6: =U6*G6 -> 0 | O6: =V6*H6 -> 0 | P6: =W6*I6 -> 0 | R6: 0 | S6: 0 | T6: 0 | U6: 0 | V6: 0 | W6: 0
A7: LLM inference / dialogue | B7: tokens (1k blended) | C7: =S7 -> 0.00552 | D7: 5 | E7: =Assumptions!$B$9 -> 10 | F7: =Assumptions!$B$9 -> 10 | G7: =Assumptions!$B$9 -> 10 | H7: =Assumptions!$B$9 -> 10 | I7: =Assumptions!$B$9 -> 10 | K7: =R7*D7 -> 0.0092 | L7: =S7*E7 -> 0.0552 | M7: =T7*F7 -> 0.0552 | N7: =U7*G7 -> 0.0552 | O7: =V7*H7 -> 0.0552 | P7: =W7*I7 -> 0.0552 | R7: ='Tool — LLM'!$C$14*Assumptions!$B$40 -> 0.00184 | S7: ='Tool — LLM'!$C$15*Assumptions!$B$40 -> 0.00552 | T7: ='Tool — LLM'!$C$16*Assumptions!$B$40 -> 0.00552 | U7: ='Tool — LLM'!$C$17*Assumptions!$B$40 -> 0.00552 | V7: ='Tool — LLM'!$C$18*Assumptions!$B$40 -> 0.00552 | W7: ='Tool — LLM'!$C$19*Assumptions!$B$40 -> 0.00552
A8: Voice — ASR (speech-to-text) | B8: voice-minutes | C8: =S8 -> 0.003864 | D8: =Assumptions!$B$6*Assumptions!$B$5 -> 4.5 | E8: =Assumptions!$B$6*Assumptions!$B$5 -> 4.5 | F8: =Assumptions!$B$6*Assumptions!$B$5 -> 4.5 | G8: =Assumptions!$B$6*Assumptions!$B$5 -> 4.5 | H8: =Assumptions!$B$6*Assumptions!$B$5 -> 4.5 | I8: =Assumptions!$B$6*Assumptions!$B$5 -> 4.5 | K8: =R8*D8 -> 0.017388 | L8: =S8*E8 -> 0.017388 | M8: =T8*F8 -> 0.017388 | N8: =U8*G8 -> 0.017388 | O8: =V8*H8 -> 0.017388 | P8: =W8*I8 -> 0.017388 | R8: ='Tool — Voice AI'!$C$14*Assumptions!$B$40 -> 0.003864 | S8: ='Tool — Voice AI'!$C$15*Assumptions!$B$40 -> 0.003864 | T8: ='Tool — Voice AI'!$C$16*Assumptions!$B$40 -> 0.003864 | U8: ='Tool — Voice AI'!$C$17*Assumptions!$B$40 -> 0.003864 | V8: ='Tool — Voice AI'!$C$18*Assumptions!$B$40 -> 0.003864 | W8: ='Tool — Voice AI'!$C$19*Assumptions!$B$40 -> 0.003864
A9: Pronunciation assessment (user speech) | B9: minutes (user speech) | C9: =S9 -> 0.0046 | D9: =Assumptions!$B$10*D8 -> 4.5 | E9: =Assumptions!$B$10*E8 -> 4.5 | F9: =Assumptions!$B$10*F8 -> 4.5 | G9: =Assumptions!$B$10*G8 -> 4.5 | H9: =Assumptions!$B$10*H8 -> 4.5 | I9: =Assumptions!$B$10*I8 -> 4.5 | K9: =R9*D9 -> 0.0207 | L9: =S9*E9 -> 0.0207 | M9: =T9*F9 -> 0.0207 | N9: =U9*G9 -> 0.0207 | O9: =V9*H9 -> 0.0207 | P9: =W9*I9 -> 0.0207 | R9: ='Tool — Pronunciation'!$C$13*Assumptions!$B$40 -> 0.0046 | S9: ='Tool — Pronunciation'!$C$14*Assumptions!$B$40 -> 0.0046 | T9: ='Tool — Pronunciation'!$C$15*Assumptions!$B$40 -> 0.0046 | U9: ='Tool — Pronunciation'!$C$16*Assumptions!$B$40 -> 0.0046 | V9: ='Tool — Pronunciation'!$C$17*Assumptions!$B$40 -> 0.0046 | W9: ='Tool — Pronunciation'!$C$18*Assumptions!$B$40 -> 0.0046
A10: Voice — TTS (text-to-speech) | B10: voice-minutes | C10: =S10 -> 0.00621 | D10: 1.5 | E10: 4.5 | F10: 4.5 | G10: 4.5 | H10: 4.5 | I10: 4.5 | K10: =R10*D10 -> 0.009315 | L10: =S10*E10 -> 0.027945 | M10: =T10*F10 -> 0.027945 | N10: =U10*G10 -> 0.027945 | O10: =V10*H10 -> 0.027945 | P10: =W10*I10 -> 0.027945 | R10: ='Tool — Voice AI'!$C$30*Assumptions!$B$40 -> 0.00621 | S10: ='Tool — Voice AI'!$C$31*Assumptions!$B$40 -> 0.00621 | T10: ='Tool — Voice AI'!$C$32*Assumptions!$B$40 -> 0.00621 | U10: ='Tool — Voice AI'!$C$33*Assumptions!$B$40 -> 0.00621 | V10: ='Tool — Voice AI'!$C$34*Assumptions!$B$40 -> 0.00621 | W10: ='Tool — Voice AI'!$C$35*Assumptions!$B$40 -> 0.00621
A11: Payment processing — excluded (see P&L) | B11: — | C11: =S11 -> 0 | D11: 0 | E11: 0 | F11: 0 | G11: 0 | H11: 0 | I11: 0 | K11: =R11*D11 -> 0 | L11: =S11*E11 -> 0 | M11: =T11*F11 -> 0 | N11: =U11*G11 -> 0 | O11: =V11*H11 -> 0 | P11: =W11*I11 -> 0 | R11: 0 | S11: 0 | T11: 0 | U11: 0 | V11: 0 | W11: 0
A12: Variable Cost Session | K12: =SUM(K6:K11) -> 0.056603 | L12: =SUM(L6:L11) -> 0.121233 | M12: =SUM(M6:M11) -> 0.121233 | N12: =SUM(N6:N11) -> 0.121233 | O12: =SUM(O6:O11) -> 0.121233 | P12: =SUM(P6:P11) -> 0.121233
A13: Content/curriculum generation (amortised €/session) | K13: ='Content Generation'!$B$34/Assumptions!$B$41 -> 0.02180477 | L13: ='Content Generation'!$B$34/Assumptions!$B$41 -> 0.02180477 | M13: ='Content Generation'!$B$34/Assumptions!$B$41 -> 0.02180477 | N13: ='Content Generation'!$B$34/Assumptions!$B$41 -> 0.02180477 | O13: ='Content Generation'!$B$34/Assumptions!$B$41 -> 0.02180477 | P13: ='Content Generation'!$B$34/Assumptions!$B$41 -> 0.02180477
A14: TOTAL COST / SESSION incl. content (€) | K14: =K12+K13 -> 0.07840777 | L14: =L12+L13 -> 0.14303777 | M14: =M12+M13 -> 0.14303777 | N14: =N12+N13 -> 0.14303777 | O14: =O12+O13 -> 0.14303777 | P14: =P12+P13 -> 0.14303777
A16: Human Teacher
A17: Feature | B17: Unit driver
A18: Human teacher (live + prep) — costed per booking | B18: 1 session | C18: 8.6 | D18: =(Assumptions!$B$19+Assumptions!$B$20)*(1+Assumptions!$B$21/(1-Assumptions!$B$21)*Assumptions!$B$22) -> 16.677778
A20: AI tutor
A21: Feature | B21: Unit driver | C21: Unit € (Plus ref) | D21: Free intensity | E21: Plus intensity | F21: Pro intensity | G21: Career intensity | H21: Premium intensity | I21: Enterprise intensity | K21: Cost / Free (€) | L21: Cost / Plus (€) | M21: Cost / Pro (€) | N21: Cost / Career (€) | O21: Cost / Premium (€) | P21: Cost / Enterprise (€) | R21: Free unit € | S21: Plus unit € | T21: Pro unit € | U21: Career unit € | V21: Premium unit € | W21: Enterprise unit €
A22: AI tutor (interactive avatar) | B22: avatar-minutes | C22: =S22 -> 0.0092 | D22: =Assumptions!$B$5 -> 30 | E22: =Assumptions!$B$5 -> 30 | F22: =Assumptions!$B$5 -> 30 | G22: =Assumptions!$B$5 -> 30 | H22: =Assumptions!$B$5 -> 30 | I22: =Assumptions!$B$5 -> 30 | K22: =R22*D22 -> 0.276 | L22: =S22*E22 -> 0.276 | M22: =T22*F22 -> 0.276 | N22: =U22*G22 -> 0.276 | O22: =V22*H22 -> 2.76 | P22: =W22*I22 -> 2.76 | R22: ='Tool — Avatar'!$C$18*Assumptions!$B$40 -> 0.0092 | S22: ='Tool — Avatar'!$C$19*Assumptions!$B$40 -> 0.0092 | T22: ='Tool — Avatar'!$C$20*Assumptions!$B$40 -> 0.0092 | U22: ='Tool — Avatar'!$C$21*Assumptions!$B$40 -> 0.0092 | V22: ='Tool — Avatar'!$C$22*Assumptions!$B$40 -> 0.092 | W22: ='Tool — Avatar'!$C$23*Assumptions!$B$40 -> 0.092
A23: Voice — ASR (speech-to-text) | B23: voice-minutes | C23: =S23 -> 0.003864 | D23: =D22 -> 30 | E23: =E22 -> 30 | F23: =F22 -> 30 | G23: =G22 -> 30 | H23: =H22 -> 30 | I23: =I22 -> 30 | K23: =R23*D23*IF('Tool — Avatar'!$B$18="Talkio.ai",0,1) -> 0.11592 | L23: =S23*E23*IF('Tool — Avatar'!$B$19="Talkio.ai",0,1) -> 0.11592 | M23: =T23*F23*IF('Tool — Avatar'!$B$20="Talkio.ai",0,1) -> 0.11592 | N23: =U23*G23*IF('Tool — Avatar'!$B$21="Talkio.ai",0,1) -> 0.11592 | O23: =V23*H23*IF('Tool — Avatar'!$B$22="Talkio.ai",0,1) -> 0.11592 | P23: =W23*I23*IF('Tool — Avatar'!$B$23="Talkio.ai",0,1) -> 0.11592 | R23: ='Tool — Voice AI'!$C$14*Assumptions!$B$40 -> 0.003864 | S23: ='Tool — Voice AI'!$C$15*Assumptions!$B$40 -> 0.003864 | T23: ='Tool — Voice AI'!$C$16*Assumptions!$B$40 -> 0.003864 | U23: ='Tool — Voice AI'!$C$17*Assumptions!$B$40 -> 0.003864 | V23: ='Tool — Voice AI'!$C$18*Assumptions!$B$40 -> 0.003864 | W23: ='Tool — Voice AI'!$C$19*Assumptions!$B$40 -> 0.003864
A24: Voice — TTS (text-to-speech) | B24: voice-minutes | C24: =S24 -> 0.00621 | D24: =D23/2 -> 15 | E24: =E23/2 -> 15 | F24: =F23/2 -> 15 | G24: =G23/2 -> 15 | H24: =H23/2 -> 15 | I24: =I23/2 -> 15 | K24: =R24*D24*IF('Tool — Avatar'!$B$18="Talkio.ai",0,1) -> 0.09315 | L24: =S24*E24*IF('Tool — Avatar'!$B$19="Talkio.ai",0,1) -> 0.09315 | M24: =T24*F24*IF('Tool — Avatar'!$B$20="Talkio.ai",0,1) -> 0.09315 | N24: =U24*G24*IF('Tool — Avatar'!$B$21="Talkio.ai",0,1) -> 0.09315 | O24: =V24*H24*IF('Tool — Avatar'!$B$22="Talkio.ai",0,1) -> 0.09315 | P24: =W24*I24*IF('Tool — Avatar'!$B$23="Talkio.ai",0,1) -> 0.09315 | R24: ='Tool — Voice AI'!$C$30*Assumptions!$B$40 -> 0.00621 | S24: ='Tool — Voice AI'!$C$31*Assumptions!$B$40 -> 0.00621 | T24: ='Tool — Voice AI'!$C$32*Assumptions!$B$40 -> 0.00621 | U24: ='Tool — Voice AI'!$C$33*Assumptions!$B$40 -> 0.00621 | V24: ='Tool — Voice AI'!$C$34*Assumptions!$B$40 -> 0.00621 | W24: ='Tool — Voice AI'!$C$35*Assumptions!$B$40 -> 0.00621
A25: Variable Cost AI Tutor | K25: =SUM(K22:K24) -> 0.48507 | L25: =SUM(L22:L24) -> 0.48507 | M25: =SUM(M22:M24) -> 0.48507 | N25: =SUM(N22:N24) -> 0.48507 | O25: =SUM(O22:O24) -> 2.96907 | P25: =SUM(P22:P24) -> 2.96907
A26: Content/curriculum generation (amortised €/session) | K26: ='Content Generation'!$B$34/Assumptions!$B$41 -> 0.02180477 | L26: ='Content Generation'!$B$34/Assumptions!$B$41 -> 0.02180477 | M26: ='Content Generation'!$B$34/Assumptions!$B$41 -> 0.02180477 | N26: ='Content Generation'!$B$34/Assumptions!$B$41 -> 0.02180477 | O26: ='Content Generation'!$B$34/Assumptions!$B$41 -> 0.02180477 | P26: ='Content Generation'!$B$34/Assumptions!$B$41 -> 0.02180477
A27: TOTAL COST / SESSION incl. content (€) | K27: =K25+K26 -> 0.50687477 | L27: =L25+L26 -> 0.50687477 | M27: =M25+M26 -> 0.50687477 | N27: =N25+N26 -> 0.50687477 | O27: =O25+O26 -> 2.9908748 | P27: =P25+P26 -> 2.9908748
A32: SRIKANT'S SIMPLIFIED MODEL — per 1,000 users / month (5 tiers)
A33: Reverse-engineered from Srikant’s table: flat $2 AI/user/mo · teacher light · ~16% app-store fee · LTV ≈ 16.5 × monthly price. Sessions/mo = added assumption (not in his model).
A34: App-store / payment fee % of revenue | B34: 0.16
A35: Tier | B35: Users /1k | C35: Price $/mo | D35: AI $/user/mo | E35: Teacher $/user/mo | F35: Sessions/user/mo | G35: Price / session $ | H35: Cost / session $ | I35: Revenue $/mo | J35: AI+Teacher $/mo | K35: App-fee $/mo | L35: Gross profit $/mo | M35: LTV $
A36: Free | B36: 800 | C36: 0 | D36: 2 | E36: 0 | F36: 8 | G36: =IFERROR(C36/F36,0) -> 0 | H36: =IFERROR((D36+E36)/F36,0) -> 0.25 | I36: =B36*C36 -> 0 | J36: =B36*(D36+E36) -> 1600 | K36: =I36*$B$34 -> 0 | L36: =I36-J36-K36 -> -1600 | M36: =C36*16.5 -> 0
A37: Plus | B37: 60 | C37: 19 | D37: 2 | E37: 0 | F37: 10 | G37: =IFERROR(C37/F37,0) -> 1.9 | H37: =IFERROR((D37+E37)/F37,0) -> 0.2 | I37: =B37*C37 -> 1140 | J37: =B37*(D37+E37) -> 120 | K37: =I37*$B$34 -> 182.4 | L37: =I37-J37-K37 -> 837.6 | M37: =C37*16.5 -> 313.5
A38: Pro | B38: 60 | C38: 49 | D38: 2 | E38: 3.75 | F38: 12 | G38: =IFERROR(C38/F38,0) -> 4.0833333 | H38: =IFERROR((D38+E38)/F38,0) -> 0.47916667 | I38: =B38*C38 -> 2940 | J38: =B38*(D38+E38) -> 345 | K38: =I38*$B$34 -> 470.4 | L38: =I38-J38-K38 -> 2124.6 | M38: =C38*16.5 -> 808.5
A39: Career | B39: 40 | C39: 40 | D39: 2 | E39: 5 | F39: 10 | G39: =IFERROR(C39/F39,0) -> 4 | H39: =IFERROR((D39+E39)/F39,0) -> 0.7 | I39: =B39*C39 -> 1600 | J39: =B39*(D39+E39) -> 280 | K39: =I39*$B$34 -> 256 | L39: =I39-J39-K39 -> 1064 | M39: =C39*16.5 -> 660
A40: Premium | B40: 40 | C40: 100 | D40: 2 | E40: 15 | F40: 15 | G40: =IFERROR(C40/F40,0) -> 6.6666667 | H40: =IFERROR((D40+E40)/F40,0) -> 1.1333333 | I40: =B40*C40 -> 4000 | J40: =B40*(D40+E40) -> 680 | K40: =I40*$B$34 -> 640 | L40: =I40-J40-K40 -> 2680 | M40: =C40*16.5 -> 1650
A41: TOTAL | B41: =SUM(B36:B40) -> 1000 | I41: =SUM(I36:I40) -> 9680 | J41: =SUM(J36:J40) -> 3025 | K41: =SUM(K36:K40) -> 1548.8 | L41: =SUM(L36:L40) -> 5106.2

Sheet User & Revenue Model
A1: USER & REVENUE MODEL — Free / Plus / Pro / Career / Premium / Enterprise
A2: BLUE = input · BLACK = formula · GREEN = link · YELLOW = key assumption. Practice & Tutor sessions costed independently; revenue $→€ via Assumptions!B40.
A4: USER BASE & CONVERSION FUNNEL
A5: Freemium signups | B5: 250000
A6: Free → paid conversion rate | B6: 0.2 | C6: Stated range 18–25%
A7: Total paid subscribers (excl. Enterprise) | B7: =B5*B6 -> 50000
A8: % of paid on Plus (remainder) | B8: =1-B9-B10-B11 -> 0.4
A9: % of paid on Pro | B9: 0.3
A10: % of paid on Career | B10: 0.2
A11: % of paid on Premium | B11: 0.1
A12: Plus subscribers | B12: =B7*B8 -> 20000
A13: Pro subscribers | B13: =B7*B9 -> 15000
A14: Career subscribers | B14: =B7*B10 -> 10000
A15: Premium subscribers | B15: =B7*B11 -> 5000
A16: Free (non-converting) users | B16: =B5-B7 -> 200000 | C16: Cost-bearing, no revenue
A17: Enterprise seats (B2B) | B17: =B5/5 -> 50000 | C17: B2B seats — Pro-style usage
A18: Total cost-bearing users | B18: =B16+B12+B13+B14+B15+B17 -> 300000
A20: SEGMENT ECONOMICS (annual)
B21: Free | C21: Plus | D21: Pro | E21: Career | F21: Premium | G21: Enterprise | H21: Total
A22: Subscribers / users | B22: =B16 -> 200000 | C22: =B12 -> 20000 | D22: =B13 -> 15000 | E22: =B14 -> 10000 | F22: =B15 -> 5000 | G22: =B17 -> 50000 | H22: =SUM(B22:G22) -> 300000
A23: Plan price ($/seat/mo) | B23: 0 | C23: =Assumptions!B13 -> 19 | D23: =Assumptions!B14 -> 49 | E23: =Assumptions!B17 -> 39 | F23: =Assumptions!B15 -> 100 | G23: 149
A24: AI practice sessions / user / mo | B24: 5 | C24: 10 | D24: 8 | E24: 10 | F24: 6 | G24: 6
A25: AI tutor sessions / user / mo | B25: 0 | C25: 2 | D25: 4 | E25: 4 | F25: 8 | G25: 4
A26: Human sessions / user / mo | B26: 0.05 | C26: 0 | D26: 2 | E26: 1 | F26: 2 | G26: 2
A27: Annual AI practice sessions | B27: =B22*B24*12 -> 12000000 | C27: =C22*C24*12 -> 2400000 | D27: =D22*D24*12 -> 1440000 | E27: =E22*E24*12 -> 1200000 | F27: =F22*F24*12 -> 360000 | G27: =G22*G24*12 -> 3600000 | H27: =SUM(B27:G27) -> 21000000
A28: Annual AI tutor sessions | B28: =B22*B25*12 -> 0 | C28: =C22*C25*12 -> 480000 | D28: =D22*D25*12 -> 720000 | E28: =E22*E25*12 -> 480000 | F28: =F22*F25*12 -> 480000 | G28: =G22*G25*12 -> 2400000 | H28: =SUM(B28:G28) -> 4560000
A29: Annual human sessions | B29: =B22*B26*12 -> 120000 | C29: =C22*C26*12 -> 0 | D29: =D22*D26*12 -> 360000 | E29: =E22*E26*12 -> 120000 | F29: =F22*F26*12 -> 120000 | G29: =G22*G26*12 -> 1200000 | H29: =SUM(B29:G29) -> 1920000
A30: AI practice cost / session (€) | B30: ='Feature Cost Build'!K14 -> 0.07840777 | C30: ='Feature Cost Build'!L14 -> 0.14303777 | D30: ='Feature Cost Build'!M14 -> 0.14303777 | E30: ='Feature Cost Build'!N14 -> 0.14303777 | F30: ='Feature Cost Build'!O14 -> 0.14303777 | G30: ='Feature Cost Build'!P14 -> 0.14303777
A31: AI tutor cost / session (€) | B31: ='Feature Cost Build'!K27 -> 0.50687477 | C31: ='Feature Cost Build'!L27 -> 0.50687477 | D31: ='Feature Cost Build'!M27 -> 0.50687477 | E31: ='Feature Cost Build'!N27 -> 0.50687477 | F31: ='Feature Cost Build'!O27 -> 2.9908748 | G31: ='Feature Cost Build'!P27 -> 2.9908748
A32: Human cost / session (€) | B32: ='Feature Cost Build'!$C$18 -> 8.6 | C32: ='Feature Cost Build'!$C$18 -> 8.6 | D32: ='Feature Cost Build'!$C$18 -> 8.6 | E32: ='Feature Cost Build'!$C$18 -> 8.6 | F32: ='Feature Cost Build'!$C$18 -> 8.6 | G32: ='Feature Cost Build'!$C$18 -> 8.6
A33: Cost / month (€) | B33: =B32*B26+B25*B31+B24*B30 -> 0.82203885 | C33: =C32*C26+C25*C31+C24*C30 -> 2.4441272 | D33: =D32*D26+D25*D31+D24*D30 -> 20.371801 | E33: =E32*E26+E25*E31+E24*E30 -> 12.057877 | F33: =F32*F26+F25*F31+F24*F30 -> 41.985225 | G33: =G32*G26+G25*G31+G24*G30 -> 30.021726
A34: Annual AI practice cost (€) | B34: =B27*B30 -> 940893.24 | C34: =C27*C30 -> 343290.65 | D34: =D27*D30 -> 205974.39 | E34: =E27*E30 -> 171645.32 | F34: =F27*F30 -> 51493.597 | G34: =G27*G30 -> 514935.97 | H34: =SUM(B34:G34) -> 2228233.2
A35: Annual AI tutor cost (€) | B35: =B28*B31 -> 0 | C35: =C28*C31 -> 243299.89 | D35: =D28*D31 -> 364949.83 | E35: =E28*E31 -> 243299.89 | F35: =F28*F31 -> 1435619.9 | G35: =G28*G31 -> 7178099.4 | H35: =SUM(B35:G35) -> 9465269
A36: Annual AI cost (€) | B36: =SUM(B34:B35) -> 940893.24 | C36: =SUM(C34:C35) -> 586590.54 | D36: =SUM(D34:D35) -> 570924.22 | E36: =SUM(E34:E35) -> 414945.21 | F36: =SUM(F34:F35) -> 1487113.5 | G36: =SUM(G34:G35) -> 7693035.4 | H36: =SUM(H34:H35) -> 11693502
A37: Annual human cost (€) | B37: =B29*B32 -> 1032000 | C37: =C29*C32 -> 0 | D37: =D29*D32 -> 3096000 | E37: =E29*E32 -> 1032000 | F37: =F29*F32 -> 1032000 | G37: =G29*G32 -> 10320000 | H37: =SUM(B37:G37) -> 16512000
A38: Annual variable cost (€) | B38: =B34+B35+B37 -> 1972893.2 | C38: =C34+C35+C37 -> 586590.54 | D38: =D34+D35+D37 -> 3666924.2 | E38: =E34+E35+E37 -> 1446945.2 | F38: =F34+F35+F37 -> 2519113.5 | G38: =G34+G35+G37 -> 18013035 | H38: =SUM(B38:G38) -> 28205502
A39: Annual revenue ($) | B39: =B22*B23*12 -> 0 | C39: =C22*C23*12 -> 4560000 | D39: =D22*D23*12 -> 8820000 | E39: =E22*E23*12 -> 4680000 | F39: =F22*F23*12 -> 6000000 | G39: =G22*G23*12 -> 89400000 | H39: =SUM(B39:G39) -> 113460000
A40: Annual revenue (€) | B40: =B39*Assumptions!$B$40 -> 0 | C40: =C39*Assumptions!$B$40 -> 4195200 | D40: =D39*Assumptions!$B$40 -> 8114400 | E40: =E39*Assumptions!$B$40 -> 4305600 | F40: =F39*Assumptions!$B$40 -> 5520000 | G40: =G39*Assumptions!$B$40 -> 82248000 | H40: =SUM(B40:G40) -> 104383200
A41: Margin (€) | B41: =B40-B38 -> -1972893.2 | C41: =C40-C38 -> 3608609.5 | D41: =D40-D38 -> 4447475.8 | E41: =E40-E38 -> 2858654.8 | F41: =F40-F38 -> 3000886.5 | G41: =G40-G38 -> 64234965 | H41: =SUM(B41:G41) -> 76177698
A42: Contribution margin (%) | B42: =IF(B40=0,"n/a",1-B38/B40) -> n/a | C42: =IF(C40=0,"n/a",1-C38/C40) -> 0.86017579 | D42: =IF(D40=0,"n/a",1-D38/D40) -> 0.54809669 | E42: =IF(E40=0,"n/a",1-E38/E40) -> 0.66393877 | F42: =IF(F40=0,"n/a",1-F38/F40) -> 0.54363886 | G42: =IF(G40=0,"n/a",1-G38/G40) -> 0.7809912 | H42: =IF(H40=0,"n/a",1-H38/H40) -> 0.72978887
...

Sheet Content Generation
A1: CONTENT / CURRICULUM GENERATION — AI-ASSISTED HYBRID BUILD
A2: BLUE = input · BLACK = formula · GREEN = cross-sheet link · YELLOW = key assumption. Feeds Assumptions!B28 (curriculum line).
A4: CONTENT CATALOG SCOPE
A5: Languages in catalog | B5: 12 | C5: Distinct languages offered
A6: CEFR levels per language (A1–C2) | B6: 6 | C6: A1, A2, B1, B2, C1, C2
A7: Lessons per level | B7: 50 | C7: Authored lesson units per level
A8: Total lessons in catalog | B8: =B5*B6*B7 -> 3600 | C8: languages x levels x lessons
A10: PER-LESSON GENERATION COST — AI-ASSISTED HYBRID
A11: AI draft (LLM generation)
A12: Tokens per lesson (blended in+out) | B12: 50000 | C12: Prompt + generated lesson content
A13: LLM cost per 1k tokens (€) | B13: ='Tool — LLM'!$C$15*Assumptions!$B$40 -> 0.00552 | C13: Selected LLM USD price × FX (Assumptions!B5)
A14: AI generation cost / lesson (€) | B14: =B12/1000*B13 -> 0.276
A15: Human review & edit
A16: Editor / SME hours per lesson | B16: 4 | C16: Instructional-design review of AI draft
A17: Loaded editor rate (€/hr) | B17: 60 | C17: Fully-loaded hourly cost
A18: Human review cost / lesson (€) | B18: =B16*B17 -> 240 | C18: hours x rate
A19: Media & localization
A20: Media / audio / localization per lesson (€) | B20: 50 | C20: Recording, images, QA per lesson
A21: TOTAL COST PER LESSON (€) | B21: =B14+B18+B20 -> 290.276 | C21: AI + human + media
A23: ONE-TIME BUILD (amortised)
A24: Total initial build cost (€) | B24: =B8*B21 -> 1044993.6 | C24: total lessons x cost/lesson
A25: Amortisation period (years) | B25: 3 | C25: Useful life of authored catalog
A26: Amortised build cost (€/yr) | B26: =B24/B25 -> 348331.2 | C26: build / years
A28: ANNUAL REFRESH
A29: Annual refresh rate (% of catalog/yr) | B29: 0.2 | C29: Share of lessons re-authored each year
A30: Lessons refreshed per year | B30: =B8*B29 -> 720 | C30: total lessons x refresh %
A31: Annual refresh cost (€/yr) | B31: =B30*B21 -> 208998.72 | C31: refreshed lessons x cost/lesson
A33: TOTAL ANNUAL CONTENT GENERATION COST
A34: TOTAL CONTENT GENERATION (€/yr) | B34: =B26+B31 -> 557329.92 | C34: Amortised build + annual refresh → feeds Assumptions!B28

Sheet Tool — Avatar
A1: AVATAR VENDOR DECISION
A2: Per-minute video avatar. NOTE: Talkio.ai bundles ASR+TTS+LLM — selecting it zeroes that tier’s separate voice cost.
A4: VENDOR COMPARISON
A5: Vendor | B5: Price (USD) | C5: Unit | D5: Notes
A6: Simli Trinity-1 | B6: 0.01 | C6: $/min | D6: Lip-sync only — you add voice
A7: Simli standard | B7: 0.05 | C7: $/min | D7: Simli has NO public pricing page (404 Jun2026) - API/contact-sales. Figure is estimate | E7: https://www.simli.com/pricing
A8: HeyGen LiveAvatar Lite | B8: 0.1 | C8: $/min | D8: HeyGen consumer plans are credit-based video gen; interactive-avatar (streaming) API = enterprise/quote. Not public per-min. Estimate | E8: https://www.heygen.com/pricing
A9: Anam.ai Starter | B9: 0.15 | C9: $/min | D9: Conversational; check voice bundling
A10: HeyGen LiveAvatar Full | B10: 0.19 | C10: $/min | D10: Higher fidelity
A11: Tavus CVI | B11: 0.37 | C11: $/min | D11: Conversational video; bundles voice. NOT validated live | E11: https://www.tavus.io/pricing
A12: D-ID Streaming | B12: 5.9 | C12: $/min | D12: Premium/enterprise
A13: Talkio.ai | B13: 0.3 | C13: $/min | D13: Talkio bundles ASR+TTS+LLM. Price is placeholder — confirm vs contract (char + per-seat)
A14: On-device (in-house) | B14: 0.005 | C14: $/min | D14: Local rendering
A16: SELECTED VENDOR — per tier (Free / Plus / Pro / Career / Premium / Enterprise)
A17: Tier | B17: Vendor (change me) | C17: Price (USD)
A18: Free | B18: Simli Trinity-1 | C18: =VLOOKUP(B18,$A$6:$B$14,2,FALSE()) -> 0.01
A19: Plus | B19: Simli Trinity-1 | C19: =VLOOKUP(B19,$A$6:$B$14,2,FALSE()) -> 0.01
A20: Pro | B20: Simli Trinity-1 | C20: =VLOOKUP(B20,$A$6:$B$14,2,FALSE()) -> 0.01
A21: Career | B21: Simli Trinity-1 | C21: =VLOOKUP(B21,$A$6:$B$14,2,FALSE()) -> 0.01
A22: Premium | B22: HeyGen LiveAvatar Lite | C22: =VLOOKUP(B22,$A$6:$B$14,2,FALSE()) -> 0.1
A23: Enterprise | B23: HeyGen LiveAvatar Lite | C23: =VLOOKUP(B23,$A$6:$B$14,2,FALSE()) -> 0.1

Sheet Tool — Voice AI
A1: VOICE — ASR (speech-to-text) + TTS (text-to-speech) — priced SEPARATELY
A2: ASR and TTS have very different pricing, so split. Per-minute, per tier. Azure = current Berlitz voice stack.
A4: ASR / SPEECH-TO-TEXT — VENDOR COMPARISON
A5: Vendor | B5: Price (USD) | C5: Unit | D5: Notes
A6: Azure Speech (committed) | B6: 0.0083 | C6: $/min | D6: Azure STT committed: $0.50/hr @50k-hr tier = $0.0083/min; 10k-hr tier $0.65/hr=$0.0108; PAYG $1/hr. Validated Jun2026 | E6: https://azure.microsoft.com/en-us/pricing/details/speech/
A7: Deepgram Nova | B7: 0.0042 | C7: $/min | D7: Nova-3 Monolingual, Growth (prepaid annual ~20% off); PAYG $0.0048 promo. Validated Jun 2026 | E7: https://deepgram.com/pricing
A8: Whisper (self-hosted) | B8: 0.006 | C8: $/min | D8: OSS self-host; infra cost. ~$0.006/min ref | E8: https://deepgram.com/pricing
A9: OpenAI gpt-4o-mini-transcribe | B9: 0.003 | C9: $/min | D9: gpt-4o-mini-transcribe $0.003/min (gpt-4o-transcribe $0.006). Validated Jun2026
A10: On-device (in-house) | B10: 0.002 | C10: $/min | D10: Local model
A12: SELECTED ASR — per tier (Free / Plus / Pro / Career / Premium / Enterprise)
A13: Tier | B13: Vendor (change me) | C13: Price (USD)
A14: Free | B14: Deepgram Nova | C14: =VLOOKUP(B14,$A$6:$B$10,2,FALSE()) -> 0.0042
A15: Plus | B15: Deepgram Nova | C15: =VLOOKUP(B15,$A$6:$B$10,2,FALSE()) -> 0.0042
A16: Pro | B16: Deepgram Nova | C16: =VLOOKUP(B16,$A$6:$B$10,2,FALSE()) -> 0.0042
A17: Career | B17: Deepgram Nova | C17: =VLOOKUP(B17,$A$6:$B$10,2,FALSE()) -> 0.0042
A18: Premium | B18: Deepgram Nova | C18: =VLOOKUP(B18,$A$6:$B$10,2,FALSE()) -> 0.0042
A19: Enterprise | B19: Deepgram Nova | C19: =VLOOKUP(B19,$A$6:$B$10,2,FALSE()) -> 0.0042
A20: TTS / TEXT-TO-SPEECH — VENDOR COMPARISON
A21: Vendor | B21: Price (USD) | C21: Unit | D21: Notes
A22: Azure Neural TTS (committed) | B22: 0.00675 | C22: $/min | D22: Azure Neural TTS committed $7.50/1M chars (2,000M tier) x ~900 ch/min = $0.0068/min (=EUR6.451/1M). Validated Jun2026 | E22: https://azure.microsoft.com/en-us/pricing/details/speech/
A23: OpenAI TTS | B23: 0.015 | C23: $/min | D23: OpenAI now token/realtime-centric; classic tts ~$15/1M chars (~$0.0135/min); confirm. Page validated Jun2026 | E23: https://platform.openai.com/docs/pricing
A24: ElevenLabs Turbo | B24: 0.05 | C24: $/min | D24: ElevenLabs Business plan, low-latency TTS ~$0.05/min; Enterprise lower at scale. Validated Jun 2026 | E24: https://elevenlabs.io/pricing
A25: ElevenLabs Premium | B25: 0.17 | C25: $/min | D25: ElevenLabs standard quality ~$0.17/min (Creator..Business). Validated Jun 2026 | E25: https://elevenlabs.io/pricing
A26: On-device (in-house) | B26: 0.01 | C26: $/min | D26: Local model
A28: SELECTED TTS — per tier (Free / Plus / Pro / Career / Premium / Enterprise)
A29: Tier | B29: Vendor (change me) | C29: Price (USD)
A30: Free | B30: Azure Neural TTS (committed) | C30: =VLOOKUP(B30,$A$22:$B$26,2,FALSE()) -> 0.00675
A31: Plus | B31: Azure Neural TTS (committed) | C31: =VLOOKUP(B31,$A$22:$B$26,2,FALSE()) -> 0.00675
A32: Pro | B32: Azure Neural TTS (committed) | C32: =VLOOKUP(B32,$A$22:$B$26,2,FALSE()) -> 0.00675
A33: Career | B33: Azure Neural TTS (committed) | C33: =VLOOKUP(B33,$A$22:$B$26,2,FALSE()) -> 0.00675
A34: Premium | B34: Azure Neural TTS (committed) | C34: =VLOOKUP(B34,$A$22:$B$26,2,FALSE()) -> 0.00675
A35: Enterprise | B35: Azure Neural TTS (committed) | C35: =VLOOKUP(B35,$A$22:$B$26,2,FALSE()) -> 0.00675

Sheet Tool — Pronunciation
A1: PRONUNCIATION ASSESSMENT — time-based ($/min), runs on user speech
A2: Runs whenever the user speaks = user-speech (STT) minutes x coverage (Assumptions!B10). Azure = current Berlitz stack. Validated Jun 2026.
A4: VENDOR COMPARISON
A5: Vendor | B5: Price (USD) | C5: Unit | D5: Notes
A6: Azure Pronunciation Assessment | B6: 0.005 | C6: $/min | D6: $0.30/hr PAYG; CURRENT Berlitz stack (Teams) | E6: https://azure.microsoft.com/en-us/pricing/details/speech/
A7: Azure committed (50k-hr) | B7: 0.0025 | C7: $/min | D7: $0.15/hr committed tier (2M-user scale) | E7: https://azure.microsoft.com/en-us/pricing/details/speech/
A8: Speechace (per-utterance, est) | B8: 0.02 | C8: $/min | D8: Natively per-utterance; rough per-min equiv | E8: https://www.speechace.com/ | F8: https://shop.speechace.com/subscription/signup-api/speechace-for-developers/speechace_api_premium_500_monthly
A9: On-device (in-house) | B9: 0.001 | C9: $/min | D9: Local model
A11: SELECTED VENDOR — per tier (Free / Plus / Pro / Career / Premium / Enterprise)
A12: Tier | B12: Vendor (change me) | C12: Price (USD)
A13: Free | B13: Azure Pronunciation Assessment | C13: =VLOOKUP(B13,$A$6:$B$9,2,FALSE()) -> 0.005
A14: Plus | B14: Azure Pronunciation Assessment | C14: =VLOOKUP(B14,$A$6:$B$9,2,FALSE()) -> 0.005
A15: Pro | B15: Azure Pronunciation Assessment | C15: =VLOOKUP(B15,$A$6:$B$9,2,FALSE()) -> 0.005
A16: Career | B16: Azure Pronunciation Assessment | C16: =VLOOKUP(B16,$A$6:$B$9,2,FALSE()) -> 0.005
A17: Premium | B17: Azure Pronunciation Assessment | C17: =VLOOKUP(B17,$A$6:$B$9,2,FALSE()) -> 0.005
A18: Enterprise | B18: Azure Pronunciation Assessment | C18: =VLOOKUP(B18,$A$6:$B$9,2,FALSE()) -> 0.005

Sheet Tool — LLM
A1: LLM (TEXT) VENDOR DECISION
A2: Blended input+output token cost. Per 1,000 tokens.
A4: VENDOR COMPARISON
A5: Vendor | B5: Price (USD) | C5: Unit | D5: Notes
A6: Claude Haiku 4.5 | B6: 0.002 | C6: $/1k tokens (blended) | D6: Haiku 4.5: $1 in / $5 out per MTok; blended ~3:1 mix = ~$2/MTok. Batch -50%. Validated Jun 2026 | E6: https://claude.com/pricing
A7: Claude Sonnet 4.6 (default) | B7: 0.006 | C7: $/1k tokens (blended) | D7: Sonnet 4.6: $3 in / $15 out per MTok; blended ~3:1 = ~$6/MTok. Validated Jun 2026 | E7: https://claude.com/pricing
A8: Claude Opus 4.6 | B8: 0.01 | C8: $/1k tokens (blended) | D8: Opus 4.8: $5 in / $25 out per MTok; blended ~3:1 = ~$10/MTok. Validated Jun 2026 | E8: https://claude.com/pricing
A9: GPT-class equivalent | B9: 0.003 | C9: $/1k tokens (blended) | D9: Pricing comparable
A10: OSS self-hosted | B10: 0.0003 | C10: $/1k tokens (blended) | D10: Requires infra investment
A11: On-device (in-house) | B11: 0.0001 | C11: $/1k tokens (blended) | D11: In-house on-device small model
A12: SELECTED VENDOR — per tier (Free / Plus / Pro / Career / Premium / Enterprise)
A13: Tier | B13: Vendor (change me) | C13: Price (USD)
A14: Free | B14: Claude Haiku 4.5 | C14: =VLOOKUP(B14,$A$6:$B$11,2,FALSE()) -> 0.002
A15: Plus | B15: Claude Sonnet 4.6 (default) | C15: =VLOOKUP(B15,$A$6:$B$11,2,FALSE()) -> 0.006
A16: Pro | B16: Claude Sonnet 4.6 (default) | C16: =VLOOKUP(B16,$A$6:$B$11,2,FALSE()) -> 0.006
A17: Career | B17: Claude Sonnet 4.6 (default) | C17: =VLOOKUP(B17,$A$6:$B$11,2,FALSE()) -> 0.006
A18: Premium | B18: Claude Sonnet 4.6 (default) | C18: =VLOOKUP(B18,$A$6:$B$11,2,FALSE()) -> 0.006
A19: Enterprise | B19: Claude Sonnet 4.6 (default) | C19: =VLOOKUP(B19,$A$6:$B$11,2,FALSE()) -> 0.006

Sheet Open Items
A1: OPEN ITEMS — refine before any decision (tiers per berlitz-mobile-app.md)
A3: CATEGORY | B3: STATUS | C3: ITEM
A4: Volume | B4: Placeholder 1M/yr | C4: Annual sessions for fixed allocation — confirm year-3 target
A5: Baseline | B5: Confirmed (550k/800) | C5: Global EU/JP/US, no franchises
A6: Engagement | B6: Now modelled (User & Revenue) | C6: Sessions/user/mo per segment + DAU; refine 4–8 range & enterprise frequency
A7: Tier mix | B7: Modelled as scenarios | C7: Pick target mix once strategy lands
A8: Tool — Voice AI | B8: OpenAI Realtime default | C8: Validate per actual vendor
A9: Tool — Avatar | B9: HeyGen Lite default | C9: Trial Simli, Anam vs. Talkio.ai baseline for fidelity
A10: Tool — Pronunciation | B10: Speechace default | C10: Vendor & pricing — could self-host
A11: Tool — LLM | B11: Claude Sonnet default | C11: Token budget per session is biggest uncertainty
A12: No-show | B12: Placeholder 10% / 50%-pay | C12: Actual rate from Berlitz ops
A13: Curriculum content | B13: Now modelled (Content Gen sheet) | C13: Validate per-lesson inputs: tokens/lesson, editor hours, refresh %, catalog scope
A14: Closed-loop engine | B14: Placeholder €300k/yr | C14: Build cost for adaptive engine
... A29: Markets | B29: India + Chile pilot | C29: Rs pricing (999/1999); 1k-signup conversion matrix in doc for pilot sizing
